{"sections":[],"schemaVersion":{"major":0,"minor":3,"patch":0},"variants":[{"paths":["\/documentation\/snowplowtracker\/trackererror\/error"],"traits":[{"interfaceLanguage":"swift"}]}],"identifier":{"url":"doc:\/\/SnowplowTracker\/documentation\/SnowplowTracker\/TrackerError\/error","interfaceLanguage":"swift"},"kind":"symbol","metadata":{"fragments":[{"text":"var","kind":"keyword"},{"text":" ","kind":"text"},{"kind":"identifier","text":"error"},{"text":": ","kind":"text"},{"kind":"typeIdentifier","text":"Error","preciseIdentifier":"s:s5ErrorP"},{"kind":"text","text":"?"}],"symbolKind":"property","roleHeading":"Instance Property","title":"error","modules":[{"name":"SnowplowTracker"}],"externalID":"c:@M@SnowplowTracker@objc(cs)SPTrackerError(py)error","role":"symbol"},"hierarchy":{"paths":[["doc:\/\/SnowplowTracker\/documentation\/SnowplowTracker","doc:\/\/SnowplowTracker\/documentation\/SnowplowTracker\/TrackerError"]]},"abstract":[{"text":"Error involved in the error.","type":"text"}],"primaryContentSections":[{"declarations":[{"platforms":["macOS"],"languages":["swift"],"tokens":[{"kind":"attribute","text":"@objc"},{"kind":"text","text":" "},{"text":"var","kind":"keyword"},{"kind":"text","text":" "},{"kind":"identifier","text":"error"},{"text":": ","kind":"text"},{"kind":"typeIdentifier","preciseIdentifier":"s:s5ErrorP","text":"Error"},{"kind":"text","text":"?"}]}],"kind":"declarations"}],"references":{"doc://SnowplowTracker/documentation/SnowplowTracker":{"type":"topic","url":"\/documentation\/snowplowtracker","title":"SnowplowTracker","abstract":[],"identifier":"doc:\/\/SnowplowTracker\/documentation\/SnowplowTracker","role":"collection","kind":"symbol"},"doc://SnowplowTracker/documentation/SnowplowTracker/TrackerError/error":{"fragments":[{"kind":"keyword","text":"var"},{"kind":"text","text":" "},{"kind":"identifier","text":"error"},{"text":": ","kind":"text"},{"kind":"typeIdentifier","preciseIdentifier":"s:s5ErrorP","text":"Error"},{"kind":"text","text":"?"}],"kind":"symbol","abstract":[{"text":"Error involved in the error.","type":"text"}],"type":"topic","title":"error","url":"\/documentation\/snowplowtracker\/trackererror\/error","identifier":"doc:\/\/SnowplowTracker\/documentation\/SnowplowTracker\/TrackerError\/error","role":"symbol"},"doc://SnowplowTracker/documentation/SnowplowTracker/TrackerError":{"kind":"symbol","url":"\/documentation\/snowplowtracker\/trackererror","identifier":"doc:\/\/SnowplowTracker\/documentation\/SnowplowTracker\/TrackerError","fragments":[{"text":"class","kind":"keyword"},{"kind":"text","text":" "},{"text":"TrackerError","kind":"identifier"}],"title":"TrackerError","type":"topic","abstract":[{"text":"Tracker error event used in diagnostic autotracking.","type":"text"}],"role":"symbol","navigatorTitle":[{"text":"TrackerError","kind":"identifier"}]}}}