{"sections":[],"identifier":{"url":"doc:\/\/SnowplowTracker\/documentation\/SnowplowTracker\/TrackerError\/error","interfaceLanguage":"swift"},"variants":[{"paths":["\/documentation\/snowplowtracker\/trackererror\/error"],"traits":[{"interfaceLanguage":"swift"}]}],"hierarchy":{"paths":[["doc:\/\/SnowplowTracker\/documentation\/SnowplowTracker","doc:\/\/SnowplowTracker\/documentation\/SnowplowTracker\/TrackerError"]]},"abstract":[{"text":"Error involved in the error.","type":"text"}],"schemaVersion":{"patch":0,"major":0,"minor":3},"kind":"symbol","metadata":{"roleHeading":"Instance Property","role":"symbol","title":"error","fragments":[{"text":"var","kind":"keyword"},{"text":" ","kind":"text"},{"kind":"identifier","text":"error"},{"text":": ","kind":"text"},{"text":"Error","kind":"typeIdentifier","preciseIdentifier":"s:s5ErrorP"},{"text":"?","kind":"text"}],"modules":[{"name":"SnowplowTracker"}],"symbolKind":"property","externalID":"c:@M@SnowplowTracker@objc(cs)SPTrackerError(py)error"},"primaryContentSections":[{"declarations":[{"tokens":[{"kind":"attribute","text":"@objc"},{"text":" ","kind":"text"},{"text":"var","kind":"keyword"},{"text":" ","kind":"text"},{"kind":"identifier","text":"error"},{"text":": ","kind":"text"},{"text":"Error","kind":"typeIdentifier","preciseIdentifier":"s:s5ErrorP"},{"text":"?","kind":"text"}],"languages":["swift"],"platforms":["macOS"]}],"kind":"declarations"}],"references":{"doc://SnowplowTracker/documentation/SnowplowTracker":{"title":"SnowplowTracker","url":"\/documentation\/snowplowtracker","abstract":[],"kind":"symbol","role":"collection","type":"topic","identifier":"doc:\/\/SnowplowTracker\/documentation\/SnowplowTracker"},"doc://SnowplowTracker/documentation/SnowplowTracker/TrackerError/error":{"abstract":[{"text":"Error involved in the error.","type":"text"}],"url":"\/documentation\/snowplowtracker\/trackererror\/error","identifier":"doc:\/\/SnowplowTracker\/documentation\/SnowplowTracker\/TrackerError\/error","title":"error","role":"symbol","fragments":[{"kind":"keyword","text":"var"},{"text":" ","kind":"text"},{"kind":"identifier","text":"error"},{"text":": ","kind":"text"},{"preciseIdentifier":"s:s5ErrorP","text":"Error","kind":"typeIdentifier"},{"text":"?","kind":"text"}],"kind":"symbol","type":"topic"},"doc://SnowplowTracker/documentation/SnowplowTracker/TrackerError":{"abstract":[{"text":"Tracker error event used in diagnostic autotracking.","type":"text"}],"url":"\/documentation\/snowplowtracker\/trackererror","navigatorTitle":[{"kind":"identifier","text":"TrackerError"}],"identifier":"doc:\/\/SnowplowTracker\/documentation\/SnowplowTracker\/TrackerError","title":"TrackerError","role":"symbol","fragments":[{"text":"class","kind":"keyword"},{"kind":"text","text":" "},{"kind":"identifier","text":"TrackerError"}],"kind":"symbol","type":"topic"}}}