{"primaryContentSections":[{"declarations":[{"tokens":[{"kind":"attribute","text":"@objc"},{"text":" ","kind":"text"},{"text":"var","kind":"keyword"},{"kind":"text","text":" "},{"text":"source","kind":"identifier"},{"kind":"text","text":": "},{"preciseIdentifier":"s:SS","text":"String","kind":"typeIdentifier"}],"languages":["swift"],"platforms":["macOS"]}],"kind":"declarations"}],"abstract":[{"text":"Class name or source where the error appeared.","type":"text"}],"metadata":{"symbolKind":"property","title":"source","externalID":"c:@M@SnowplowTracker@objc(cs)SPTrackerError(py)source","role":"symbol","fragments":[{"kind":"keyword","text":"var"},{"text":" ","kind":"text"},{"text":"source","kind":"identifier"},{"text":": ","kind":"text"},{"text":"String","preciseIdentifier":"s:SS","kind":"typeIdentifier"}],"roleHeading":"Instance Property","modules":[{"name":"SnowplowTracker"}]},"kind":"symbol","variants":[{"paths":["\/documentation\/snowplowtracker\/trackererror\/source"],"traits":[{"interfaceLanguage":"swift"}]}],"hierarchy":{"paths":[["doc:\/\/SnowplowTracker\/documentation\/SnowplowTracker","doc:\/\/SnowplowTracker\/documentation\/SnowplowTracker\/TrackerError"]]},"identifier":{"interfaceLanguage":"swift","url":"doc:\/\/SnowplowTracker\/documentation\/SnowplowTracker\/TrackerError\/source"},"schemaVersion":{"major":0,"patch":0,"minor":3},"sections":[],"references":{"doc://SnowplowTracker/documentation/SnowplowTracker":{"url":"\/documentation\/snowplowtracker","abstract":[],"title":"SnowplowTracker","role":"collection","type":"topic","kind":"symbol","identifier":"doc:\/\/SnowplowTracker\/documentation\/SnowplowTracker"},"doc://SnowplowTracker/documentation/SnowplowTracker/TrackerError":{"kind":"symbol","role":"symbol","identifier":"doc:\/\/SnowplowTracker\/documentation\/SnowplowTracker\/TrackerError","url":"\/documentation\/snowplowtracker\/trackererror","type":"topic","title":"TrackerError","navigatorTitle":[{"text":"TrackerError","kind":"identifier"}],"abstract":[{"text":"Tracker error event used in diagnostic autotracking.","type":"text"}],"fragments":[{"text":"class","kind":"keyword"},{"text":" ","kind":"text"},{"kind":"identifier","text":"TrackerError"}]},"doc://SnowplowTracker/documentation/SnowplowTracker/TrackerError/source":{"kind":"symbol","title":"source","fragments":[{"text":"var","kind":"keyword"},{"text":" ","kind":"text"},{"text":"source","kind":"identifier"},{"kind":"text","text":": "},{"preciseIdentifier":"s:SS","kind":"typeIdentifier","text":"String"}],"url":"\/documentation\/snowplowtracker\/trackererror\/source","type":"topic","role":"symbol","abstract":[{"text":"Class name or source where the error appeared.","type":"text"}],"identifier":"doc:\/\/SnowplowTracker\/documentation\/SnowplowTracker\/TrackerError\/source"}}}