{"sections":[],"identifier":{"interfaceLanguage":"swift","url":"doc:\/\/SnowplowTracker\/documentation\/SnowplowTracker\/TrackerError\/source"},"abstract":[{"text":"Class name or source where the error appeared.","type":"text"}],"metadata":{"role":"symbol","modules":[{"name":"SnowplowTracker"}],"fragments":[{"kind":"keyword","text":"var"},{"text":" ","kind":"text"},{"kind":"identifier","text":"source"},{"text":": ","kind":"text"},{"preciseIdentifier":"s:SS","text":"String","kind":"typeIdentifier"}],"title":"source","symbolKind":"property","externalID":"c:@M@SnowplowTracker@objc(cs)SPTrackerError(py)source","roleHeading":"Instance Property"},"hierarchy":{"paths":[["doc:\/\/SnowplowTracker\/documentation\/SnowplowTracker","doc:\/\/SnowplowTracker\/documentation\/SnowplowTracker\/TrackerError"]]},"variants":[{"traits":[{"interfaceLanguage":"swift"}],"paths":["\/documentation\/snowplowtracker\/trackererror\/source"]}],"kind":"symbol","primaryContentSections":[{"declarations":[{"platforms":["macOS"],"languages":["swift"],"tokens":[{"kind":"attribute","text":"@objc"},{"text":" ","kind":"text"},{"kind":"keyword","text":"var"},{"kind":"text","text":" "},{"kind":"identifier","text":"source"},{"kind":"text","text":": "},{"kind":"typeIdentifier","preciseIdentifier":"s:SS","text":"String"}]}],"kind":"declarations"}],"schemaVersion":{"minor":3,"major":0,"patch":0},"references":{"doc://SnowplowTracker/documentation/SnowplowTracker/TrackerError":{"abstract":[{"text":"Tracker error event used in diagnostic autotracking.","type":"text"}],"url":"\/documentation\/snowplowtracker\/trackererror","navigatorTitle":[{"kind":"identifier","text":"TrackerError"}],"identifier":"doc:\/\/SnowplowTracker\/documentation\/SnowplowTracker\/TrackerError","title":"TrackerError","role":"symbol","fragments":[{"text":"class","kind":"keyword"},{"kind":"text","text":" "},{"kind":"identifier","text":"TrackerError"}],"kind":"symbol","type":"topic"},"doc://SnowplowTracker/documentation/SnowplowTracker/TrackerError/source":{"abstract":[{"text":"Class name or source where the error appeared.","type":"text"}],"url":"\/documentation\/snowplowtracker\/trackererror\/source","identifier":"doc:\/\/SnowplowTracker\/documentation\/SnowplowTracker\/TrackerError\/source","title":"source","role":"symbol","fragments":[{"kind":"keyword","text":"var"},{"text":" ","kind":"text"},{"text":"source","kind":"identifier"},{"kind":"text","text":": "},{"preciseIdentifier":"s:SS","kind":"typeIdentifier","text":"String"}],"kind":"symbol","type":"topic"},"doc://SnowplowTracker/documentation/SnowplowTracker":{"title":"SnowplowTracker","url":"\/documentation\/snowplowtracker","abstract":[],"kind":"symbol","role":"collection","type":"topic","identifier":"doc:\/\/SnowplowTracker\/documentation\/SnowplowTracker"}}}